2017-11-17 09:50:31,792 [Thread-21:123145500323840] [django.request:135] [exception:handle_uncaught_exception] [ERROR]- Internal Server Error: /user/info/
Traceback (most recent call last):
  File "/Users/zhanlingjie/Documents/virEnv/GPapp/lib/python3.4/site-packages/django/core/handlers/exception.py", line 41, in inner
    response = get_response(request)
  File "/Users/zhanlingjie/Documents/virEnv/GPapp/lib/python3.4/site-packages/django/core/handlers/base.py", line 187, in _get_response
    response = self.process_exception_by_middleware(e, request)
  File "/Users/zhanlingjie/Documents/virEnv/GPapp/lib/python3.4/site-packages/django/core/handlers/base.py", line 185, in _get_response
    response = wrapped_callback(request, *callback_args, **callback_kwargs)
  File "/Users/zhanlingjie/Documents/mypython/GG/z_user/views.py", line 21, in info
    return render_to_response('user/index.html')
  File "/Users/zhanlingjie/Documents/virEnv/GPapp/lib/python3.4/site-packages/django/shortcuts.py", line 21, in render_to_response
    content = loader.render_to_string(template_name, context, using=using)
  File "/Users/zhanlingjie/Documents/virEnv/GPapp/lib/python3.4/site-packages/django/template/loader.py", line 67, in render_to_string
    template = get_template(template_name, using=using)
  File "/Users/zhanlingjie/Documents/virEnv/GPapp/lib/python3.4/site-packages/django/template/loader.py", line 25, in get_template
    raise TemplateDoesNotExist(template_name, chain=chain)
django.template.exceptions.TemplateDoesNotExist: user/index.html
2018-03-18 06:06:05,150 [Thread-44:123145562763264] [django.request:135] [exception:handle_uncaught_exception] [ERROR]- Internal Server Error: /api/search_home
Traceback (most recent call last):
  File "/Users/zhanlingjie/Documents/virEnv/GPapp/lib/python3.4/site-packages/django/core/handlers/exception.py", line 41, in inner
    response = get_response(request)
  File "/Users/zhanlingjie/Documents/virEnv/GPapp/lib/python3.4/site-packages/django/core/handlers/base.py", line 187, in _get_response
    response = self.process_exception_by_middleware(e, request)
  File "/Users/zhanlingjie/Documents/virEnv/GPapp/lib/python3.4/site-packages/django/core/handlers/base.py", line 185, in _get_response
    response = wrapped_callback(request, *callback_args, **callback_kwargs)
  File "/Users/zhanlingjie/Documents/virEnv/GPapp/lib/python3.4/site-packages/django/views/decorators/csrf.py", line 58, in wrapped_view
    return view_func(*args, **kwargs)
  File "/Users/zhanlingjie/Documents/mypython/GG/api/views.py", line 21, in search_home
    db.gg_search.insert({'user': uid, 'content': content,  'create_time': int(time.time())})
  File "/Users/zhanlingjie/Documents/virEnv/GPapp/lib/python3.4/site-packages/pymongo/collection.py", line 2935, in insert
    check_keys, manipulate, write_concern)
  File "/Users/zhanlingjie/Documents/virEnv/GPapp/lib/python3.4/site-packages/pymongo/collection.py", line 598, in _insert
    bypass_doc_val, session)
  File "/Users/zhanlingjie/Documents/virEnv/GPapp/lib/python3.4/site-packages/pymongo/collection.py", line 578, in _insert_one
    True, _insert_command, session)
  File "/Users/zhanlingjie/Documents/virEnv/GPapp/lib/python3.4/site-packages/pymongo/mongo_client.py", line 1098, in _retryable_write
    with self._tmp_session(session) as s:
  File "/Library/Frameworks/Python.framework/Versions/3.4/lib/python3.4/contextlib.py", line 59, in __enter__
    return next(self.gen)
  File "/Users/zhanlingjie/Documents/virEnv/GPapp/lib/python3.4/site-packages/pymongo/mongo_client.py", line 1404, in _tmp_session
    s = self._ensure_session(session)
  File "/Users/zhanlingjie/Documents/virEnv/GPapp/lib/python3.4/site-packages/pymongo/mongo_client.py", line 1391, in _ensure_session
    return self.start_session(causal_consistency=False)
  File "/Users/zhanlingjie/Documents/virEnv/GPapp/lib/python3.4/site-packages/pymongo/mongo_client.py", line 1369, in start_session
    server_session = self._get_server_session()
  File "/Users/zhanlingjie/Documents/virEnv/GPapp/lib/python3.4/site-packages/pymongo/mongo_client.py", line 1377, in _get_server_session
    return self._topology.get_server_session()
  File "/Users/zhanlingjie/Documents/virEnv/GPapp/lib/python3.4/site-packages/pymongo/topology.py", line 416, in get_server_session
    None)
  File "/Users/zhanlingjie/Documents/virEnv/GPapp/lib/python3.4/site-packages/pymongo/topology.py", line 199, in _select_servers_loop
    self._error_message(selector))
pymongo.errors.ServerSelectionTimeoutError: 192.168.0.113:27017: [Errno 64] Host is down
2018-03-18 06:06:05,929 [Thread-45:123145546997760] [django.request:135] [exception:handle_uncaught_exception] [ERROR]- Internal Server Error: /api/search_home
Traceback (most recent call last):
  File "/Users/zhanlingjie/Documents/virEnv/GPapp/lib/python3.4/site-packages/django/core/handlers/exception.py", line 41, in inner
    response = get_response(request)
  File "/Users/zhanlingjie/Documents/virEnv/GPapp/lib/python3.4/site-packages/django/core/handlers/base.py", line 187, in _get_response
    response = self.process_exception_by_middleware(e, request)
  File "/Users/zhanlingjie/Documents/virEnv/GPapp/lib/python3.4/site-packages/django/core/handlers/base.py", line 185, in _get_response
    response = wrapped_callback(request, *callback_args, **callback_kwargs)
  File "/Users/zhanlingjie/Documents/virEnv/GPapp/lib/python3.4/site-packages/django/views/decorators/csrf.py", line 58, in wrapped_view
    return view_func(*args, **kwargs)
  File "/Users/zhanlingjie/Documents/mypython/GG/api/views.py", line 21, in search_home
    db.gg_search.insert({'user': uid, 'content': content,  'create_time': int(time.time())})
  File "/Users/zhanlingjie/Documents/virEnv/GPapp/lib/python3.4/site-packages/pymongo/collection.py", line 2935, in insert
    check_keys, manipulate, write_concern)
  File "/Users/zhanlingjie/Documents/virEnv/GPapp/lib/python3.4/site-packages/pymongo/collection.py", line 598, in _insert
    bypass_doc_val, session)
  File "/Users/zhanlingjie/Documents/virEnv/GPapp/lib/python3.4/site-packages/pymongo/collection.py", line 578, in _insert_one
    True, _insert_command, session)
  File "/Users/zhanlingjie/Documents/virEnv/GPapp/lib/python3.4/site-packages/pymongo/mongo_client.py", line 1098, in _retryable_write
    with self._tmp_session(session) as s:
  File "/Library/Frameworks/Python.framework/Versions/3.4/lib/python3.4/contextlib.py", line 59, in __enter__
    return next(self.gen)
  File "/Users/zhanlingjie/Documents/virEnv/GPapp/lib/python3.4/site-packages/pymongo/mongo_client.py", line 1404, in _tmp_session
    s = self._ensure_session(session)
  File "/Users/zhanlingjie/Documents/virEnv/GPapp/lib/python3.4/site-packages/pymongo/mongo_client.py", line 1391, in _ensure_session
    return self.start_session(causal_consistency=False)
  File "/Users/zhanlingjie/Documents/virEnv/GPapp/lib/python3.4/site-packages/pymongo/mongo_client.py", line 1369, in start_session
    server_session = self._get_server_session()
  File "/Users/zhanlingjie/Documents/virEnv/GPapp/lib/python3.4/site-packages/pymongo/mongo_client.py", line 1377, in _get_server_session
    return self._topology.get_server_session()
  File "/Users/zhanlingjie/Documents/virEnv/GPapp/lib/python3.4/site-packages/pymongo/topology.py", line 416, in get_server_session
    None)
  File "/Users/zhanlingjie/Documents/virEnv/GPapp/lib/python3.4/site-packages/pymongo/topology.py", line 199, in _select_servers_loop
    self._error_message(selector))
pymongo.errors.ServerSelectionTimeoutError: 192.168.0.113:27017: [Errno 64] Host is down
2018-03-18 06:06:06,156 [Thread-46:123145594294272] [django.request:135] [exception:handle_uncaught_exception] [ERROR]- Internal Server Error: /api/search_home
Traceback (most recent call last):
  File "/Users/zhanlingjie/Documents/virEnv/GPapp/lib/python3.4/site-packages/django/core/handlers/exception.py", line 41, in inner
    response = get_response(request)
  File "/Users/zhanlingjie/Documents/virEnv/GPapp/lib/python3.4/site-packages/django/core/handlers/base.py", line 187, in _get_response
    response = self.process_exception_by_middleware(e, request)
  File "/Users/zhanlingjie/Documents/virEnv/GPapp/lib/python3.4/site-packages/django/core/handlers/base.py", line 185, in _get_response
    response = wrapped_callback(request, *callback_args, **callback_kwargs)
  File "/Users/zhanlingjie/Documents/virEnv/GPapp/lib/python3.4/site-packages/django/views/decorators/csrf.py", line 58, in wrapped_view
    return view_func(*args, **kwargs)
  File "/Users/zhanlingjie/Documents/mypython/GG/api/views.py", line 21, in search_home
    db.gg_search.insert({'user': uid, 'content': content,  'create_time': int(time.time())})
  File "/Users/zhanlingjie/Documents/virEnv/GPapp/lib/python3.4/site-packages/pymongo/collection.py", line 2935, in insert
    check_keys, manipulate, write_concern)
  File "/Users/zhanlingjie/Documents/virEnv/GPapp/lib/python3.4/site-packages/pymongo/collection.py", line 598, in _insert
    bypass_doc_val, session)
  File "/Users/zhanlingjie/Documents/virEnv/GPapp/lib/python3.4/site-packages/pymongo/collection.py", line 578, in _insert_one
    True, _insert_command, session)
  File "/Users/zhanlingjie/Documents/virEnv/GPapp/lib/python3.4/site-packages/pymongo/mongo_client.py", line 1098, in _retryable_write
    with self._tmp_session(session) as s:
  File "/Library/Frameworks/Python.framework/Versions/3.4/lib/python3.4/contextlib.py", line 59, in __enter__
    return next(self.gen)
  File "/Users/zhanlingjie/Documents/virEnv/GPapp/lib/python3.4/site-packages/pymongo/mongo_client.py", line 1404, in _tmp_session
    s = self._ensure_session(session)
  File "/Users/zhanlingjie/Documents/virEnv/GPapp/lib/python3.4/site-packages/pymongo/mongo_client.py", line 1391, in _ensure_session
    return self.start_session(causal_consistency=False)
  File "/Users/zhanlingjie/Documents/virEnv/GPapp/lib/python3.4/site-packages/pymongo/mongo_client.py", line 1369, in start_session
    server_session = self._get_server_session()
  File "/Users/zhanlingjie/Documents/virEnv/GPapp/lib/python3.4/site-packages/pymongo/mongo_client.py", line 1377, in _get_server_session
    return self._topology.get_server_session()
  File "/Users/zhanlingjie/Documents/virEnv/GPapp/lib/python3.4/site-packages/pymongo/topology.py", line 416, in get_server_session
    None)
  File "/Users/zhanlingjie/Documents/virEnv/GPapp/lib/python3.4/site-packages/pymongo/topology.py", line 199, in _select_servers_loop
    self._error_message(selector))
pymongo.errors.ServerSelectionTimeoutError: 192.168.0.113:27017: [Errno 64] Host is down
2018-03-18 06:06:06,362 [Thread-47:123145615314944] [django.request:135] [exception:handle_uncaught_exception] [ERROR]- Internal Server Error: /api/search_home
Traceback (most recent call last):
  File "/Users/zhanlingjie/Documents/virEnv/GPapp/lib/python3.4/site-packages/django/core/handlers/exception.py", line 41, in inner
    response = get_response(request)
  File "/Users/zhanlingjie/Documents/virEnv/GPapp/lib/python3.4/site-packages/django/core/handlers/base.py", line 187, in _get_response
    response = self.process_exception_by_middleware(e, request)
  File "/Users/zhanlingjie/Documents/virEnv/GPapp/lib/python3.4/site-packages/django/core/handlers/base.py", line 185, in _get_response
    response = wrapped_callback(request, *callback_args, **callback_kwargs)
  File "/Users/zhanlingjie/Documents/virEnv/GPapp/lib/python3.4/site-packages/django/views/decorators/csrf.py", line 58, in wrapped_view
    return view_func(*args, **kwargs)
  File "/Users/zhanlingjie/Documents/mypython/GG/api/views.py", line 21, in search_home
    db.gg_search.insert({'user': uid, 'content': content,  'create_time': int(time.time())})
  File "/Users/zhanlingjie/Documents/virEnv/GPapp/lib/python3.4/site-packages/pymongo/collection.py", line 2935, in insert
    check_keys, manipulate, write_concern)
  File "/Users/zhanlingjie/Documents/virEnv/GPapp/lib/python3.4/site-packages/pymongo/collection.py", line 598, in _insert
    bypass_doc_val, session)
  File "/Users/zhanlingjie/Documents/virEnv/GPapp/lib/python3.4/site-packages/pymongo/collection.py", line 578, in _insert_one
    True, _insert_command, session)
  File "/Users/zhanlingjie/Documents/virEnv/GPapp/lib/python3.4/site-packages/pymongo/mongo_client.py", line 1098, in _retryable_write
    with self._tmp_session(session) as s:
  File "/Library/Frameworks/Python.framework/Versions/3.4/lib/python3.4/contextlib.py", line 59, in __enter__
    return next(self.gen)
  File "/Users/zhanlingjie/Documents/virEnv/GPapp/lib/python3.4/site-packages/pymongo/mongo_client.py", line 1404, in _tmp_session
    s = self._ensure_session(session)
  File "/Users/zhanlingjie/Documents/virEnv/GPapp/lib/python3.4/site-packages/pymongo/mongo_client.py", line 1391, in _ensure_session
    return self.start_session(causal_consistency=False)
  File "/Users/zhanlingjie/Documents/virEnv/GPapp/lib/python3.4/site-packages/pymongo/mongo_client.py", line 1369, in start_session
    server_session = self._get_server_session()
  File "/Users/zhanlingjie/Documents/virEnv/GPapp/lib/python3.4/site-packages/pymongo/mongo_client.py", line 1377, in _get_server_session
    return self._topology.get_server_session()
  File "/Users/zhanlingjie/Documents/virEnv/GPapp/lib/python3.4/site-packages/pymongo/topology.py", line 416, in get_server_session
    None)
  File "/Users/zhanlingjie/Documents/virEnv/GPapp/lib/python3.4/site-packages/pymongo/topology.py", line 199, in _select_servers_loop
    self._error_message(selector))
pymongo.errors.ServerSelectionTimeoutError: 192.168.0.113:27017: [Errno 64] Host is down
2018-03-18 06:06:08,268 [Thread-48:123145636335616] [django.request:135] [exception:handle_uncaught_exception] [ERROR]- Internal Server Error: /api/search_home
Traceback (most recent call last):
  File "/Users/zhanlingjie/Documents/virEnv/GPapp/lib/python3.4/site-packages/django/core/handlers/exception.py", line 41, in inner
    response = get_response(request)
  File "/Users/zhanlingjie/Documents/virEnv/GPapp/lib/python3.4/site-packages/django/core/handlers/base.py", line 187, in _get_response
    response = self.process_exception_by_middleware(e, request)
  File "/Users/zhanlingjie/Documents/virEnv/GPapp/lib/python3.4/site-packages/django/core/handlers/base.py", line 185, in _get_response
    response = wrapped_callback(request, *callback_args, **callback_kwargs)
  File "/Users/zhanlingjie/Documents/virEnv/GPapp/lib/python3.4/site-packages/django/views/decorators/csrf.py", line 58, in wrapped_view
    return view_func(*args, **kwargs)
  File "/Users/zhanlingjie/Documents/mypython/GG/api/views.py", line 21, in search_home
    db.gg_search.insert({'user': uid, 'content': content,  'create_time': int(time.time())})
  File "/Users/zhanlingjie/Documents/virEnv/GPapp/lib/python3.4/site-packages/pymongo/collection.py", line 2935, in insert
    check_keys, manipulate, write_concern)
  File "/Users/zhanlingjie/Documents/virEnv/GPapp/lib/python3.4/site-packages/pymongo/collection.py", line 598, in _insert
    bypass_doc_val, session)
  File "/Users/zhanlingjie/Documents/virEnv/GPapp/lib/python3.4/site-packages/pymongo/collection.py", line 578, in _insert_one
    True, _insert_command, session)
  File "/Users/zhanlingjie/Documents/virEnv/GPapp/lib/python3.4/site-packages/pymongo/mongo_client.py", line 1098, in _retryable_write
    with self._tmp_session(session) as s:
  File "/Library/Frameworks/Python.framework/Versions/3.4/lib/python3.4/contextlib.py", line 59, in __enter__
    return next(self.gen)
  File "/Users/zhanlingjie/Documents/virEnv/GPapp/lib/python3.4/site-packages/pymongo/mongo_client.py", line 1404, in _tmp_session
    s = self._ensure_session(session)
  File "/Users/zhanlingjie/Documents/virEnv/GPapp/lib/python3.4/site-packages/pymongo/mongo_client.py", line 1391, in _ensure_session
    return self.start_session(causal_consistency=False)
  File "/Users/zhanlingjie/Documents/virEnv/GPapp/lib/python3.4/site-packages/pymongo/mongo_client.py", line 1369, in start_session
    server_session = self._get_server_session()
  File "/Users/zhanlingjie/Documents/virEnv/GPapp/lib/python3.4/site-packages/pymongo/mongo_client.py", line 1377, in _get_server_session
    return self._topology.get_server_session()
  File "/Users/zhanlingjie/Documents/virEnv/GPapp/lib/python3.4/site-packages/pymongo/topology.py", line 416, in get_server_session
    None)
  File "/Users/zhanlingjie/Documents/virEnv/GPapp/lib/python3.4/site-packages/pymongo/topology.py", line 199, in _select_servers_loop
    self._error_message(selector))
pymongo.errors.ServerSelectionTimeoutError: 192.168.0.113:27017: [Errno 64] Host is down
2018-03-18 06:06:18,961 [Thread-49:123145541742592] [django.request:135] [exception:handle_uncaught_exception] [ERROR]- Internal Server Error: /api/search_home
Traceback (most recent call last):
  File "/Users/zhanlingjie/Documents/virEnv/GPapp/lib/python3.4/site-packages/django/core/handlers/exception.py", line 41, in inner
    response = get_response(request)
  File "/Users/zhanlingjie/Documents/virEnv/GPapp/lib/python3.4/site-packages/django/core/handlers/base.py", line 187, in _get_response
    response = self.process_exception_by_middleware(e, request)
  File "/Users/zhanlingjie/Documents/virEnv/GPapp/lib/python3.4/site-packages/django/core/handlers/base.py", line 185, in _get_response
    response = wrapped_callback(request, *callback_args, **callback_kwargs)
  File "/Users/zhanlingjie/Documents/virEnv/GPapp/lib/python3.4/site-packages/django/views/decorators/csrf.py", line 58, in wrapped_view
    return view_func(*args, **kwargs)
  File "/Users/zhanlingjie/Documents/mypython/GG/api/views.py", line 21, in search_home
    db.gg_search.insert({'user': uid, 'content': content,  'create_time': int(time.time())})
  File "/Users/zhanlingjie/Documents/virEnv/GPapp/lib/python3.4/site-packages/pymongo/collection.py", line 2935, in insert
    check_keys, manipulate, write_concern)
  File "/Users/zhanlingjie/Documents/virEnv/GPapp/lib/python3.4/site-packages/pymongo/collection.py", line 598, in _insert
    bypass_doc_val, session)
  File "/Users/zhanlingjie/Documents/virEnv/GPapp/lib/python3.4/site-packages/pymongo/collection.py", line 578, in _insert_one
    True, _insert_command, session)
  File "/Users/zhanlingjie/Documents/virEnv/GPapp/lib/python3.4/site-packages/pymongo/mongo_client.py", line 1098, in _retryable_write
    with self._tmp_session(session) as s:
  File "/Library/Frameworks/Python.framework/Versions/3.4/lib/python3.4/contextlib.py", line 59, in __enter__
    return next(self.gen)
  File "/Users/zhanlingjie/Documents/virEnv/GPapp/lib/python3.4/site-packages/pymongo/mongo_client.py", line 1404, in _tmp_session
    s = self._ensure_session(session)
  File "/Users/zhanlingjie/Documents/virEnv/GPapp/lib/python3.4/site-packages/pymongo/mongo_client.py", line 1391, in _ensure_session
    return self.start_session(causal_consistency=False)
  File "/Users/zhanlingjie/Documents/virEnv/GPapp/lib/python3.4/site-packages/pymongo/mongo_client.py", line 1369, in start_session
    server_session = self._get_server_session()
  File "/Users/zhanlingjie/Documents/virEnv/GPapp/lib/python3.4/site-packages/pymongo/mongo_client.py", line 1377, in _get_server_session
    return self._topology.get_server_session()
  File "/Users/zhanlingjie/Documents/virEnv/GPapp/lib/python3.4/site-packages/pymongo/topology.py", line 416, in get_server_session
    None)
  File "/Users/zhanlingjie/Documents/virEnv/GPapp/lib/python3.4/site-packages/pymongo/topology.py", line 199, in _select_servers_loop
    self._error_message(selector))
pymongo.errors.ServerSelectionTimeoutError: 192.168.0.113:27017: [Errno 64] Host is down
2018-03-18 22:49:13,372 [Thread-22:123145492627456] [django.request:135] [exception:handle_uncaught_exception] [ERROR]- Internal Server Error: /show/index_1
Traceback (most recent call last):
  File "/Users/zhanlingjie/Documents/virEnv/GPapp/lib/python3.4/site-packages/django/core/handlers/exception.py", line 41, in inner
    response = get_response(request)
  File "/Users/zhanlingjie/Documents/virEnv/GPapp/lib/python3.4/site-packages/django/core/handlers/base.py", line 187, in _get_response
    response = self.process_exception_by_middleware(e, request)
  File "/Users/zhanlingjie/Documents/virEnv/GPapp/lib/python3.4/site-packages/django/core/handlers/base.py", line 185, in _get_response
    response = wrapped_callback(request, *callback_args, **callback_kwargs)
  File "/Users/zhanlingjie/Documents/virEnv/GPapp/lib/python3.4/site-packages/django/views/decorators/csrf.py", line 58, in wrapped_view
    return view_func(*args, **kwargs)
  File "/Users/zhanlingjie/Documents/mypython/GG/show/views.py", line 16, in index_1
    return render(request, 'show/show_1.html', locals())
  File "/Users/zhanlingjie/Documents/virEnv/GPapp/lib/python3.4/site-packages/django/shortcuts.py", line 30, in render
    content = loader.render_to_string(template_name, context, request, using=using)
  File "/Users/zhanlingjie/Documents/virEnv/GPapp/lib/python3.4/site-packages/django/template/loader.py", line 67, in render_to_string
    template = get_template(template_name, using=using)
  File "/Users/zhanlingjie/Documents/virEnv/GPapp/lib/python3.4/site-packages/django/template/loader.py", line 25, in get_template
    raise TemplateDoesNotExist(template_name, chain=chain)
django.template.exceptions.TemplateDoesNotExist: show/show_1.html
2018-03-18 22:51:35,686 [Thread-71:123145792172032] [django.request:135] [exception:handle_uncaught_exception] [ERROR]- Internal Server Error: /api/search_home
Traceback (most recent call last):
  File "/Users/zhanlingjie/Documents/virEnv/GPapp/lib/python3.4/site-packages/django/core/handlers/exception.py", line 41, in inner
    response = get_response(request)
  File "/Users/zhanlingjie/Documents/virEnv/GPapp/lib/python3.4/site-packages/django/core/handlers/base.py", line 187, in _get_response
    response = self.process_exception_by_middleware(e, request)
  File "/Users/zhanlingjie/Documents/virEnv/GPapp/lib/python3.4/site-packages/django/core/handlers/base.py", line 185, in _get_response
    response = wrapped_callback(request, *callback_args, **callback_kwargs)
  File "/Users/zhanlingjie/Documents/virEnv/GPapp/lib/python3.4/site-packages/django/views/decorators/csrf.py", line 58, in wrapped_view
    return view_func(*args, **kwargs)
  File "/Users/zhanlingjie/Documents/mypython/GG/api/views.py", line 21, in search_home
    db.gg_search.insert({'user': uid, 'content': content,  'create_time': int(time.time())})
  File "/Users/zhanlingjie/Documents/virEnv/GPapp/lib/python3.4/site-packages/pymongo/collection.py", line 2935, in insert
    check_keys, manipulate, write_concern)
  File "/Users/zhanlingjie/Documents/virEnv/GPapp/lib/python3.4/site-packages/pymongo/collection.py", line 598, in _insert
    bypass_doc_val, session)
  File "/Users/zhanlingjie/Documents/virEnv/GPapp/lib/python3.4/site-packages/pymongo/collection.py", line 578, in _insert_one
    True, _insert_command, session)
  File "/Users/zhanlingjie/Documents/virEnv/GPapp/lib/python3.4/site-packages/pymongo/mongo_client.py", line 1098, in _retryable_write
    with self._tmp_session(session) as s:
  File "/Library/Frameworks/Python.framework/Versions/3.4/lib/python3.4/contextlib.py", line 59, in __enter__
    return next(self.gen)
  File "/Users/zhanlingjie/Documents/virEnv/GPapp/lib/python3.4/site-packages/pymongo/mongo_client.py", line 1404, in _tmp_session
    s = self._ensure_session(session)
  File "/Users/zhanlingjie/Documents/virEnv/GPapp/lib/python3.4/site-packages/pymongo/mongo_client.py", line 1391, in _ensure_session
    return self.start_session(causal_consistency=False)
  File "/Users/zhanlingjie/Documents/virEnv/GPapp/lib/python3.4/site-packages/pymongo/mongo_client.py", line 1369, in start_session
    server_session = self._get_server_session()
  File "/Users/zhanlingjie/Documents/virEnv/GPapp/lib/python3.4/site-packages/pymongo/mongo_client.py", line 1377, in _get_server_session
    return self._topology.get_server_session()
  File "/Users/zhanlingjie/Documents/virEnv/GPapp/lib/python3.4/site-packages/pymongo/topology.py", line 416, in get_server_session
    None)
  File "/Users/zhanlingjie/Documents/virEnv/GPapp/lib/python3.4/site-packages/pymongo/topology.py", line 199, in _select_servers_loop
    self._error_message(selector))
pymongo.errors.ServerSelectionTimeoutError: 192.168.0.113:27017: [Errno 64] Host is down
2018-03-18 22:51:36,329 [Thread-72:123145807937536] [django.request:135] [exception:handle_uncaught_exception] [ERROR]- Internal Server Error: /api/search_home
Traceback (most recent call last):
  File "/Users/zhanlingjie/Documents/virEnv/GPapp/lib/python3.4/site-packages/django/core/handlers/exception.py", line 41, in inner
    response = get_response(request)
  File "/Users/zhanlingjie/Documents/virEnv/GPapp/lib/python3.4/site-packages/django/core/handlers/base.py", line 187, in _get_response
    response = self.process_exception_by_middleware(e, request)
  File "/Users/zhanlingjie/Documents/virEnv/GPapp/lib/python3.4/site-packages/django/core/handlers/base.py", line 185, in _get_response
    response = wrapped_callback(request, *callback_args, **callback_kwargs)
  File "/Users/zhanlingjie/Documents/virEnv/GPapp/lib/python3.4/site-packages/django/views/decorators/csrf.py", line 58, in wrapped_view
    return view_func(*args, **kwargs)
  File "/Users/zhanlingjie/Documents/mypython/GG/api/views.py", line 21, in search_home
    db.gg_search.insert({'user': uid, 'content': content,  'create_time': int(time.time())})
  File "/Users/zhanlingjie/Documents/virEnv/GPapp/lib/python3.4/site-packages/pymongo/collection.py", line 2935, in insert
    check_keys, manipulate, write_concern)
  File "/Users/zhanlingjie/Documents/virEnv/GPapp/lib/python3.4/site-packages/pymongo/collection.py", line 598, in _insert
    bypass_doc_val, session)
  File "/Users/zhanlingjie/Documents/virEnv/GPapp/lib/python3.4/site-packages/pymongo/collection.py", line 578, in _insert_one
    True, _insert_command, session)
  File "/Users/zhanlingjie/Documents/virEnv/GPapp/lib/python3.4/site-packages/pymongo/mongo_client.py", line 1098, in _retryable_write
    with self._tmp_session(session) as s:
  File "/Library/Frameworks/Python.framework/Versions/3.4/lib/python3.4/contextlib.py", line 59, in __enter__
    return next(self.gen)
  File "/Users/zhanlingjie/Documents/virEnv/GPapp/lib/python3.4/site-packages/pymongo/mongo_client.py", line 1404, in _tmp_session
    s = self._ensure_session(session)
  File "/Users/zhanlingjie/Documents/virEnv/GPapp/lib/python3.4/site-packages/pymongo/mongo_client.py", line 1391, in _ensure_session
    return self.start_session(causal_consistency=False)
  File "/Users/zhanlingjie/Documents/virEnv/GPapp/lib/python3.4/site-packages/pymongo/mongo_client.py", line 1369, in start_session
    server_session = self._get_server_session()
  File "/Users/zhanlingjie/Documents/virEnv/GPapp/lib/python3.4/site-packages/pymongo/mongo_client.py", line 1377, in _get_server_session
    return self._topology.get_server_session()
  File "/Users/zhanlingjie/Documents/virEnv/GPapp/lib/python3.4/site-packages/pymongo/topology.py", line 416, in get_server_session
    None)
  File "/Users/zhanlingjie/Documents/virEnv/GPapp/lib/python3.4/site-packages/pymongo/topology.py", line 199, in _select_servers_loop
    self._error_message(selector))
pymongo.errors.ServerSelectionTimeoutError: 192.168.0.113:27017: [Errno 64] Host is down
2018-03-18 22:51:36,509 [Thread-73:123145823703040] [django.request:135] [exception:handle_uncaught_exception] [ERROR]- Internal Server Error: /api/search_home
Traceback (most recent call last):
  File "/Users/zhanlingjie/Documents/virEnv/GPapp/lib/python3.4/site-packages/django/core/handlers/exception.py", line 41, in inner
    response = get_response(request)
  File "/Users/zhanlingjie/Documents/virEnv/GPapp/lib/python3.4/site-packages/django/core/handlers/base.py", line 187, in _get_response
    response = self.process_exception_by_middleware(e, request)
  File "/Users/zhanlingjie/Documents/virEnv/GPapp/lib/python3.4/site-packages/django/core/handlers/base.py", line 185, in _get_response
    response = wrapped_callback(request, *callback_args, **callback_kwargs)
  File "/Users/zhanlingjie/Documents/virEnv/GPapp/lib/python3.4/site-packages/django/views/decorators/csrf.py", line 58, in wrapped_view
    return view_func(*args, **kwargs)
  File "/Users/zhanlingjie/Documents/mypython/GG/api/views.py", line 21, in search_home
    db.gg_search.insert({'user': uid, 'content': content,  'create_time': int(time.time())})
  File "/Users/zhanlingjie/Documents/virEnv/GPapp/lib/python3.4/site-packages/pymongo/collection.py", line 2935, in insert
    check_keys, manipulate, write_concern)
  File "/Users/zhanlingjie/Documents/virEnv/GPapp/lib/python3.4/site-packages/pymongo/collection.py", line 598, in _insert
    bypass_doc_val, session)
  File "/Users/zhanlingjie/Documents/virEnv/GPapp/lib/python3.4/site-packages/pymongo/collection.py", line 578, in _insert_one
    True, _insert_command, session)
  File "/Users/zhanlingjie/Documents/virEnv/GPapp/lib/python3.4/site-packages/pymongo/mongo_client.py", line 1098, in _retryable_write
    with self._tmp_session(session) as s:
  File "/Library/Frameworks/Python.framework/Versions/3.4/lib/python3.4/contextlib.py", line 59, in __enter__
    return next(self.gen)
  File "/Users/zhanlingjie/Documents/virEnv/GPapp/lib/python3.4/site-packages/pymongo/mongo_client.py", line 1404, in _tmp_session
    s = self._ensure_session(session)
  File "/Users/zhanlingjie/Documents/virEnv/GPapp/lib/python3.4/site-packages/pymongo/mongo_client.py", line 1391, in _ensure_session
    return self.start_session(causal_consistency=False)
  File "/Users/zhanlingjie/Documents/virEnv/GPapp/lib/python3.4/site-packages/pymongo/mongo_client.py", line 1369, in start_session
    server_session = self._get_server_session()
  File "/Users/zhanlingjie/Documents/virEnv/GPapp/lib/python3.4/site-packages/pymongo/mongo_client.py", line 1377, in _get_server_session
    return self._topology.get_server_session()
  File "/Users/zhanlingjie/Documents/virEnv/GPapp/lib/python3.4/site-packages/pymongo/topology.py", line 416, in get_server_session
    None)
  File "/Users/zhanlingjie/Documents/virEnv/GPapp/lib/python3.4/site-packages/pymongo/topology.py", line 199, in _select_servers_loop
    self._error_message(selector))
pymongo.errors.ServerSelectionTimeoutError: 192.168.0.113:27017: [Errno 64] Host is down
2018-03-18 22:51:36,696 [Thread-74:123145839468544] [django.request:135] [exception:handle_uncaught_exception] [ERROR]- Internal Server Error: /api/search_home
Traceback (most recent call last):
  File "/Users/zhanlingjie/Documents/virEnv/GPapp/lib/python3.4/site-packages/django/core/handlers/exception.py", line 41, in inner
    response = get_response(request)
  File "/Users/zhanlingjie/Documents/virEnv/GPapp/lib/python3.4/site-packages/django/core/handlers/base.py", line 187, in _get_response
    response = self.process_exception_by_middleware(e, request)
  File "/Users/zhanlingjie/Documents/virEnv/GPapp/lib/python3.4/site-packages/django/core/handlers/base.py", line 185, in _get_response
    response = wrapped_callback(request, *callback_args, **callback_kwargs)
  File "/Users/zhanlingjie/Documents/virEnv/GPapp/lib/python3.4/site-packages/django/views/decorators/csrf.py", line 58, in wrapped_view
    return view_func(*args, **kwargs)
  File "/Users/zhanlingjie/Documents/mypython/GG/api/views.py", line 21, in search_home
    db.gg_search.insert({'user': uid, 'content': content,  'create_time': int(time.time())})
  File "/Users/zhanlingjie/Documents/virEnv/GPapp/lib/python3.4/site-packages/pymongo/collection.py", line 2935, in insert
    check_keys, manipulate, write_concern)
  File "/Users/zhanlingjie/Documents/virEnv/GPapp/lib/python3.4/site-packages/pymongo/collection.py", line 598, in _insert
    bypass_doc_val, session)
  File "/Users/zhanlingjie/Documents/virEnv/GPapp/lib/python3.4/site-packages/pymongo/collection.py", line 578, in _insert_one
    True, _insert_command, session)
  File "/Users/zhanlingjie/Documents/virEnv/GPapp/lib/python3.4/site-packages/pymongo/mongo_client.py", line 1098, in _retryable_write
    with self._tmp_session(session) as s:
  File "/Library/Frameworks/Python.framework/Versions/3.4/lib/python3.4/contextlib.py", line 59, in __enter__
    return next(self.gen)
  File "/Users/zhanlingjie/Documents/virEnv/GPapp/lib/python3.4/site-packages/pymongo/mongo_client.py", line 1404, in _tmp_session
    s = self._ensure_session(session)
  File "/Users/zhanlingjie/Documents/virEnv/GPapp/lib/python3.4/site-packages/pymongo/mongo_client.py", line 1391, in _ensure_session
    return self.start_session(causal_consistency=False)
  File "/Users/zhanlingjie/Documents/virEnv/GPapp/lib/python3.4/site-packages/pymongo/mongo_client.py", line 1369, in start_session
    server_session = self._get_server_session()
  File "/Users/zhanlingjie/Documents/virEnv/GPapp/lib/python3.4/site-packages/pymongo/mongo_client.py", line 1377, in _get_server_session
    return self._topology.get_server_session()
  File "/Users/zhanlingjie/Documents/virEnv/GPapp/lib/python3.4/site-packages/pymongo/topology.py", line 416, in get_server_session
    None)
  File "/Users/zhanlingjie/Documents/virEnv/GPapp/lib/python3.4/site-packages/pymongo/topology.py", line 199, in _select_servers_loop
    self._error_message(selector))
pymongo.errors.ServerSelectionTimeoutError: 192.168.0.113:27017: [Errno 64] Host is down
2018-03-20 06:17:00,788 [Thread-271:123145566875648] [django.request:135] [exception:handle_uncaught_exception] [ERROR]- Internal Server Error: /api/focus_people
Traceback (most recent call last):
  File "/Users/zhanlingjie/Documents/virEnv/GPapp/lib/python3.4/site-packages/django/core/handlers/exception.py", line 41, in inner
    response = get_response(request)
  File "/Users/zhanlingjie/Documents/virEnv/GPapp/lib/python3.4/site-packages/django/core/handlers/base.py", line 198, in _get_response
    "returned None instead." % (callback.__module__, view_name)
ValueError: The view api.views.focus_people didn't return an HttpResponse object. It returned None instead.
2018-03-20 06:17:01,301 [Thread-272:123145566875648] [django.request:135] [exception:handle_uncaught_exception] [ERROR]- Internal Server Error: /api/focus_people
Traceback (most recent call last):
  File "/Users/zhanlingjie/Documents/virEnv/GPapp/lib/python3.4/site-packages/django/core/handlers/exception.py", line 41, in inner
    response = get_response(request)
  File "/Users/zhanlingjie/Documents/virEnv/GPapp/lib/python3.4/site-packages/django/core/handlers/base.py", line 198, in _get_response
    "returned None instead." % (callback.__module__, view_name)
ValueError: The view api.views.focus_people didn't return an HttpResponse object. It returned None instead.
2018-03-20 06:17:01,890 [Thread-273:123145566875648] [django.request:135] [exception:handle_uncaught_exception] [ERROR]- Internal Server Error: /api/focus_people
Traceback (most recent call last):
  File "/Users/zhanlingjie/Documents/virEnv/GPapp/lib/python3.4/site-packages/django/core/handlers/exception.py", line 41, in inner
    response = get_response(request)
  File "/Users/zhanlingjie/Documents/virEnv/GPapp/lib/python3.4/site-packages/django/core/handlers/base.py", line 198, in _get_response
    "returned None instead." % (callback.__module__, view_name)
ValueError: The view api.views.focus_people didn't return an HttpResponse object. It returned None instead.
2018-03-20 06:34:36,404 [Thread-2:123145493766144] [django.request:135] [exception:handle_uncaught_exception] [ERROR]- Internal Server Error: /content/introduce/
Traceback (most recent call last):
  File "/Users/zhanlingjie/Documents/virEnv/GPapp/lib/python3.4/site-packages/django/core/handlers/exception.py", line 41, in inner
    response = get_response(request)
  File "/Users/zhanlingjie/Documents/virEnv/GPapp/lib/python3.4/site-packages/django/core/handlers/base.py", line 187, in _get_response
    response = self.process_exception_by_middleware(e, request)
  File "/Users/zhanlingjie/Documents/virEnv/GPapp/lib/python3.4/site-packages/django/core/handlers/base.py", line 185, in _get_response
    response = wrapped_callback(request, *callback_args, **callback_kwargs)
  File "/Users/zhanlingjie/Documents/virEnv/GPapp/lib/python3.4/site-packages/django/views/decorators/csrf.py", line 58, in wrapped_view
    return view_func(*args, **kwargs)
  File "/Users/zhanlingjie/Documents/mypython/GG/ContentApp/views.py", line 37, in introduce
    user_id = request.COOKIES['user_id']
KeyError: 'user_id'
2018-03-20 06:34:51,905 [Thread-6:123145493766144] [django.request:135] [exception:handle_uncaught_exception] [ERROR]- Internal Server Error: /content/introduce/
Traceback (most recent call last):
  File "/Users/zhanlingjie/Documents/virEnv/GPapp/lib/python3.4/site-packages/django/core/handlers/exception.py", line 41, in inner
    response = get_response(request)
  File "/Users/zhanlingjie/Documents/virEnv/GPapp/lib/python3.4/site-packages/django/core/handlers/base.py", line 187, in _get_response
    response = self.process_exception_by_middleware(e, request)
  File "/Users/zhanlingjie/Documents/virEnv/GPapp/lib/python3.4/site-packages/django/core/handlers/base.py", line 185, in _get_response
    response = wrapped_callback(request, *callback_args, **callback_kwargs)
  File "/Users/zhanlingjie/Documents/virEnv/GPapp/lib/python3.4/site-packages/django/views/decorators/csrf.py", line 58, in wrapped_view
    return view_func(*args, **kwargs)
  File "/Users/zhanlingjie/Documents/mypython/GG/ContentApp/views.py", line 39, in introduce
    P = UserInfo.objects.get(Account=user)
NameError: name 'user' is not defined
2018-03-20 06:35:02,276 [Thread-7:123145493766144] [django.request:135] [exception:handle_uncaught_exception] [ERROR]- Internal Server Error: /content/introduce/
Traceback (most recent call last):
  File "/Users/zhanlingjie/Documents/virEnv/GPapp/lib/python3.4/site-packages/django/core/handlers/exception.py", line 41, in inner
    response = get_response(request)
  File "/Users/zhanlingjie/Documents/virEnv/GPapp/lib/python3.4/site-packages/django/core/handlers/base.py", line 187, in _get_response
    response = self.process_exception_by_middleware(e, request)
  File "/Users/zhanlingjie/Documents/virEnv/GPapp/lib/python3.4/site-packages/django/core/handlers/base.py", line 185, in _get_response
    response = wrapped_callback(request, *callback_args, **callback_kwargs)
  File "/Users/zhanlingjie/Documents/virEnv/GPapp/lib/python3.4/site-packages/django/views/decorators/csrf.py", line 58, in wrapped_view
    return view_func(*args, **kwargs)
  File "/Users/zhanlingjie/Documents/mypython/GG/ContentApp/views.py", line 39, in introduce
    P = UserInfo.objects.get(Account=user)
NameError: name 'user' is not defined
2018-03-20 06:35:02,951 [Thread-8:123145493766144] [django.request:135] [exception:handle_uncaught_exception] [ERROR]- Internal Server Error: /content/introduce/
Traceback (most recent call last):
  File "/Users/zhanlingjie/Documents/virEnv/GPapp/lib/python3.4/site-packages/django/core/handlers/exception.py", line 41, in inner
    response = get_response(request)
  File "/Users/zhanlingjie/Documents/virEnv/GPapp/lib/python3.4/site-packages/django/core/handlers/base.py", line 187, in _get_response
    response = self.process_exception_by_middleware(e, request)
  File "/Users/zhanlingjie/Documents/virEnv/GPapp/lib/python3.4/site-packages/django/core/handlers/base.py", line 185, in _get_response
    response = wrapped_callback(request, *callback_args, **callback_kwargs)
  File "/Users/zhanlingjie/Documents/virEnv/GPapp/lib/python3.4/site-packages/django/views/decorators/csrf.py", line 58, in wrapped_view
    return view_func(*args, **kwargs)
  File "/Users/zhanlingjie/Documents/mypython/GG/ContentApp/views.py", line 39, in introduce
    P = UserInfo.objects.get(Account=user_id)
NameError: name 'user' is not defined
2018-03-20 06:35:14,013 [Thread-2:123145492078592] [django.request:135] [exception:handle_uncaught_exception] [ERROR]- Internal Server Error: /content/introduce/
Traceback (most recent call last):
  File "/Users/zhanlingjie/Documents/virEnv/GPapp/lib/python3.4/site-packages/django/core/handlers/exception.py", line 41, in inner
    response = get_response(request)
  File "/Users/zhanlingjie/Documents/virEnv/GPapp/lib/python3.4/site-packages/django/core/handlers/base.py", line 187, in _get_response
    response = self.process_exception_by_middleware(e, request)
  File "/Users/zhanlingjie/Documents/virEnv/GPapp/lib/python3.4/site-packages/django/core/handlers/base.py", line 185, in _get_response
    response = wrapped_callback(request, *callback_args, **callback_kwargs)
  File "/Users/zhanlingjie/Documents/virEnv/GPapp/lib/python3.4/site-packages/django/views/decorators/csrf.py", line 58, in wrapped_view
    return view_func(*args, **kwargs)
  File "/Users/zhanlingjie/Documents/mypython/GG/ContentApp/views.py", line 40, in introduce
    return render(request, 'content/introduce.html', locals())
  File "/Users/zhanlingjie/Documents/virEnv/GPapp/lib/python3.4/site-packages/django/shortcuts.py", line 30, in render
    content = loader.render_to_string(template_name, context, request, using=using)
  File "/Users/zhanlingjie/Documents/virEnv/GPapp/lib/python3.4/site-packages/django/template/loader.py", line 68, in render_to_string
    return template.render(context, request)
  File "/Users/zhanlingjie/Documents/virEnv/GPapp/lib/python3.4/site-packages/django/template/backends/django.py", line 66, in render
    return self.template.render(context)
  File "/Users/zhanlingjie/Documents/virEnv/GPapp/lib/python3.4/site-packages/django/template/base.py", line 207, in render
    return self._render(context)
  File "/Users/zhanlingjie/Documents/virEnv/GPapp/lib/python3.4/site-packages/django/template/base.py", line 199, in _render
    return self.nodelist.render(context)
  File "/Users/zhanlingjie/Documents/virEnv/GPapp/lib/python3.4/site-packages/django/template/base.py", line 990, in render
    bit = node.render_annotated(context)
  File "/Users/zhanlingjie/Documents/virEnv/GPapp/lib/python3.4/site-packages/django/template/base.py", line 957, in render_annotated
    return self.render(context)
  File "/Users/zhanlingjie/Documents/virEnv/GPapp/lib/python3.4/site-packages/django/template/loader_tags.py", line 177, in render
    return compiled_parent._render(context)
  File "/Users/zhanlingjie/Documents/virEnv/GPapp/lib/python3.4/site-packages/django/template/base.py", line 199, in _render
    return self.nodelist.render(context)
  File "/Users/zhanlingjie/Documents/virEnv/GPapp/lib/python3.4/site-packages/django/template/base.py", line 990, in render
    bit = node.render_annotated(context)
  File "/Users/zhanlingjie/Documents/virEnv/GPapp/lib/python3.4/site-packages/django/template/base.py", line 957, in render_annotated
    return self.render(context)
  File "/Users/zhanlingjie/Documents/virEnv/GPapp/lib/python3.4/site-packages/django/template/defaulttags.py", line 172, in render
    values = list(values)
TypeError: 'UserInfo' object is not iterable
2018-03-20 06:35:14,679 [Thread-3:123145497333760] [django.request:135] [exception:handle_uncaught_exception] [ERROR]- Internal Server Error: /content/introduce/
Traceback (most recent call last):
  File "/Users/zhanlingjie/Documents/virEnv/GPapp/lib/python3.4/site-packages/django/core/handlers/exception.py", line 41, in inner
    response = get_response(request)
  File "/Users/zhanlingjie/Documents/virEnv/GPapp/lib/python3.4/site-packages/django/core/handlers/base.py", line 187, in _get_response
    response = self.process_exception_by_middleware(e, request)
  File "/Users/zhanlingjie/Documents/virEnv/GPapp/lib/python3.4/site-packages/django/core/handlers/base.py", line 185, in _get_response
    response = wrapped_callback(request, *callback_args, **callback_kwargs)
  File "/Users/zhanlingjie/Documents/virEnv/GPapp/lib/python3.4/site-packages/django/views/decorators/csrf.py", line 58, in wrapped_view
    return view_func(*args, **kwargs)
  File "/Users/zhanlingjie/Documents/mypython/GG/ContentApp/views.py", line 40, in introduce
    return render(request, 'content/introduce.html', locals())
  File "/Users/zhanlingjie/Documents/virEnv/GPapp/lib/python3.4/site-packages/django/shortcuts.py", line 30, in render
    content = loader.render_to_string(template_name, context, request, using=using)
  File "/Users/zhanlingjie/Documents/virEnv/GPapp/lib/python3.4/site-packages/django/template/loader.py", line 68, in render_to_string
    return template.render(context, request)
  File "/Users/zhanlingjie/Documents/virEnv/GPapp/lib/python3.4/site-packages/django/template/backends/django.py", line 66, in render
    return self.template.render(context)
  File "/Users/zhanlingjie/Documents/virEnv/GPapp/lib/python3.4/site-packages/django/template/base.py", line 207, in render
    return self._render(context)
  File "/Users/zhanlingjie/Documents/virEnv/GPapp/lib/python3.4/site-packages/django/template/base.py", line 199, in _render
    return self.nodelist.render(context)
  File "/Users/zhanlingjie/Documents/virEnv/GPapp/lib/python3.4/site-packages/django/template/base.py", line 990, in render
    bit = node.render_annotated(context)
  File "/Users/zhanlingjie/Documents/virEnv/GPapp/lib/python3.4/site-packages/django/template/base.py", line 957, in render_annotated
    return self.render(context)
  File "/Users/zhanlingjie/Documents/virEnv/GPapp/lib/python3.4/site-packages/django/template/loader_tags.py", line 177, in render
    return compiled_parent._render(context)
  File "/Users/zhanlingjie/Documents/virEnv/GPapp/lib/python3.4/site-packages/django/template/base.py", line 199, in _render
    return self.nodelist.render(context)
  File "/Users/zhanlingjie/Documents/virEnv/GPapp/lib/python3.4/site-packages/django/template/base.py", line 990, in render
    bit = node.render_annotated(context)
  File "/Users/zhanlingjie/Documents/virEnv/GPapp/lib/python3.4/site-packages/django/template/base.py", line 957, in render_annotated
    return self.render(context)
  File "/Users/zhanlingjie/Documents/virEnv/GPapp/lib/python3.4/site-packages/django/template/defaulttags.py", line 172, in render
    values = list(values)
TypeError: 'UserInfo' object is not iterable
2018-03-20 06:35:15,614 [Thread-4:123145492078592] [django.request:135] [exception:handle_uncaught_exception] [ERROR]- Internal Server Error: /content/introduce/
Traceback (most recent call last):
  File "/Users/zhanlingjie/Documents/virEnv/GPapp/lib/python3.4/site-packages/django/core/handlers/exception.py", line 41, in inner
    response = get_response(request)
  File "/Users/zhanlingjie/Documents/virEnv/GPapp/lib/python3.4/site-packages/django/core/handlers/base.py", line 187, in _get_response
    response = self.process_exception_by_middleware(e, request)
  File "/Users/zhanlingjie/Documents/virEnv/GPapp/lib/python3.4/site-packages/django/core/handlers/base.py", line 185, in _get_response
    response = wrapped_callback(request, *callback_args, **callback_kwargs)
  File "/Users/zhanlingjie/Documents/virEnv/GPapp/lib/python3.4/site-packages/django/views/decorators/csrf.py", line 58, in wrapped_view
    return view_func(*args, **kwargs)
  File "/Users/zhanlingjie/Documents/mypython/GG/ContentApp/views.py", line 40, in introduce
    return render(request, 'content/introduce.html', locals())
  File "/Users/zhanlingjie/Documents/virEnv/GPapp/lib/python3.4/site-packages/django/shortcuts.py", line 30, in render
    content = loader.render_to_string(template_name, context, request, using=using)
  File "/Users/zhanlingjie/Documents/virEnv/GPapp/lib/python3.4/site-packages/django/template/loader.py", line 68, in render_to_string
    return template.render(context, request)
  File "/Users/zhanlingjie/Documents/virEnv/GPapp/lib/python3.4/site-packages/django/template/backends/django.py", line 66, in render
    return self.template.render(context)
  File "/Users/zhanlingjie/Documents/virEnv/GPapp/lib/python3.4/site-packages/django/template/base.py", line 207, in render
    return self._render(context)
  File "/Users/zhanlingjie/Documents/virEnv/GPapp/lib/python3.4/site-packages/django/template/base.py", line 199, in _render
    return self.nodelist.render(context)
  File "/Users/zhanlingjie/Documents/virEnv/GPapp/lib/python3.4/site-packages/django/template/base.py", line 990, in render
    bit = node.render_annotated(context)
  File "/Users/zhanlingjie/Documents/virEnv/GPapp/lib/python3.4/site-packages/django/template/base.py", line 957, in render_annotated
    return self.render(context)
  File "/Users/zhanlingjie/Documents/virEnv/GPapp/lib/python3.4/site-packages/django/template/loader_tags.py", line 177, in render
    return compiled_parent._render(context)
  File "/Users/zhanlingjie/Documents/virEnv/GPapp/lib/python3.4/site-packages/django/template/base.py", line 199, in _render
    return self.nodelist.render(context)
  File "/Users/zhanlingjie/Documents/virEnv/GPapp/lib/python3.4/site-packages/django/template/base.py", line 990, in render
    bit = node.render_annotated(context)
  File "/Users/zhanlingjie/Documents/virEnv/GPapp/lib/python3.4/site-packages/django/template/base.py", line 957, in render_annotated
    return self.render(context)
  File "/Users/zhanlingjie/Documents/virEnv/GPapp/lib/python3.4/site-packages/django/template/defaulttags.py", line 172, in render
    values = list(values)
TypeError: 'UserInfo' object is not iterable
2018-03-20 06:41:24,759 [Thread-2:123145334689792] [django.request:135] [exception:handle_uncaught_exception] [ERROR]- Internal Server Error: /content/introduce/
Traceback (most recent call last):
  File "/Users/zhanlingjie/Documents/virEnv/GPapp/lib/python3.4/site-packages/django/core/handlers/exception.py", line 41, in inner
    response = get_response(request)
  File "/Users/zhanlingjie/Documents/virEnv/GPapp/lib/python3.4/site-packages/django/core/handlers/base.py", line 187, in _get_response
    response = self.process_exception_by_middleware(e, request)
  File "/Users/zhanlingjie/Documents/virEnv/GPapp/lib/python3.4/site-packages/django/core/handlers/base.py", line 185, in _get_response
    response = wrapped_callback(request, *callback_args, **callback_kwargs)
  File "/Users/zhanlingjie/Documents/virEnv/GPapp/lib/python3.4/site-packages/django/views/decorators/csrf.py", line 58, in wrapped_view
    return view_func(*args, **kwargs)
  File "/Users/zhanlingjie/Documents/mypython/GG/ContentApp/views.py", line 41, in introduce
    return render(request, 'content/introduce.html', locals())
  File "/Users/zhanlingjie/Documents/virEnv/GPapp/lib/python3.4/site-packages/django/shortcuts.py", line 30, in render
    content = loader.render_to_string(template_name, context, request, using=using)
  File "/Users/zhanlingjie/Documents/virEnv/GPapp/lib/python3.4/site-packages/django/template/loader.py", line 68, in render_to_string
    return template.render(context, request)
  File "/Users/zhanlingjie/Documents/virEnv/GPapp/lib/python3.4/site-packages/django/template/backends/django.py", line 66, in render
    return self.template.render(context)
  File "/Users/zhanlingjie/Documents/virEnv/GPapp/lib/python3.4/site-packages/django/template/base.py", line 207, in render
    return self._render(context)
  File "/Users/zhanlingjie/Documents/virEnv/GPapp/lib/python3.4/site-packages/django/template/base.py", line 199, in _render
    return self.nodelist.render(context)
  File "/Users/zhanlingjie/Documents/virEnv/GPapp/lib/python3.4/site-packages/django/template/base.py", line 990, in render
    bit = node.render_annotated(context)
  File "/Users/zhanlingjie/Documents/virEnv/GPapp/lib/python3.4/site-packages/django/template/base.py", line 957, in render_annotated
    return self.render(context)
  File "/Users/zhanlingjie/Documents/virEnv/GPapp/lib/python3.4/site-packages/django/template/loader_tags.py", line 177, in render
    return compiled_parent._render(context)
  File "/Users/zhanlingjie/Documents/virEnv/GPapp/lib/python3.4/site-packages/django/template/base.py", line 199, in _render
    return self.nodelist.render(context)
  File "/Users/zhanlingjie/Documents/virEnv/GPapp/lib/python3.4/site-packages/django/template/base.py", line 990, in render
    bit = node.render_annotated(context)
  File "/Users/zhanlingjie/Documents/virEnv/GPapp/lib/python3.4/site-packages/django/template/base.py", line 957, in render_annotated
    return self.render(context)
  File "/Users/zhanlingjie/Documents/virEnv/GPapp/lib/python3.4/site-packages/django/template/defaulttags.py", line 172, in render
    values = list(values)
TypeError: 'UserInfo' object is not iterable
2018-03-20 06:41:25,225 [Thread-3:123145339944960] [django.request:135] [exception:handle_uncaught_exception] [ERROR]- Internal Server Error: /content/introduce/
Traceback (most recent call last):
  File "/Users/zhanlingjie/Documents/virEnv/GPapp/lib/python3.4/site-packages/django/core/handlers/exception.py", line 41, in inner
    response = get_response(request)
  File "/Users/zhanlingjie/Documents/virEnv/GPapp/lib/python3.4/site-packages/django/core/handlers/base.py", line 187, in _get_response
    response = self.process_exception_by_middleware(e, request)
  File "/Users/zhanlingjie/Documents/virEnv/GPapp/lib/python3.4/site-packages/django/core/handlers/base.py", line 185, in _get_response
    response = wrapped_callback(request, *callback_args, **callback_kwargs)
  File "/Users/zhanlingjie/Documents/virEnv/GPapp/lib/python3.4/site-packages/django/views/decorators/csrf.py", line 58, in wrapped_view
    return view_func(*args, **kwargs)
  File "/Users/zhanlingjie/Documents/mypython/GG/ContentApp/views.py", line 41, in introduce
    return render(request, 'content/introduce.html', locals())
  File "/Users/zhanlingjie/Documents/virEnv/GPapp/lib/python3.4/site-packages/django/shortcuts.py", line 30, in render
    content = loader.render_to_string(template_name, context, request, using=using)
  File "/Users/zhanlingjie/Documents/virEnv/GPapp/lib/python3.4/site-packages/django/template/loader.py", line 68, in render_to_string
    return template.render(context, request)
  File "/Users/zhanlingjie/Documents/virEnv/GPapp/lib/python3.4/site-packages/django/template/backends/django.py", line 66, in render
    return self.template.render(context)
  File "/Users/zhanlingjie/Documents/virEnv/GPapp/lib/python3.4/site-packages/django/template/base.py", line 207, in render
    return self._render(context)
  File "/Users/zhanlingjie/Documents/virEnv/GPapp/lib/python3.4/site-packages/django/template/base.py", line 199, in _render
    return self.nodelist.render(context)
  File "/Users/zhanlingjie/Documents/virEnv/GPapp/lib/python3.4/site-packages/django/template/base.py", line 990, in render
    bit = node.render_annotated(context)
  File "/Users/zhanlingjie/Documents/virEnv/GPapp/lib/python3.4/site-packages/django/template/base.py", line 957, in render_annotated
    return self.render(context)
  File "/Users/zhanlingjie/Documents/virEnv/GPapp/lib/python3.4/site-packages/django/template/loader_tags.py", line 177, in render
    return compiled_parent._render(context)
  File "/Users/zhanlingjie/Documents/virEnv/GPapp/lib/python3.4/site-packages/django/template/base.py", line 199, in _render
    return self.nodelist.render(context)
  File "/Users/zhanlingjie/Documents/virEnv/GPapp/lib/python3.4/site-packages/django/template/base.py", line 990, in render
    bit = node.render_annotated(context)
  File "/Users/zhanlingjie/Documents/virEnv/GPapp/lib/python3.4/site-packages/django/template/base.py", line 957, in render_annotated
    return self.render(context)
  File "/Users/zhanlingjie/Documents/virEnv/GPapp/lib/python3.4/site-packages/django/template/defaulttags.py", line 172, in render
    values = list(values)
TypeError: 'UserInfo' object is not iterable
2018-03-20 06:53:26,350 [Thread-17:123145531707392] [django.request:135] [exception:handle_uncaught_exception] [ERROR]- Internal Server Error: /content/introduce/
Traceback (most recent call last):
  File "/Users/zhanlingjie/Documents/virEnv/GPapp/lib/python3.4/site-packages/django/core/handlers/exception.py", line 41, in inner
    response = get_response(request)
  File "/Users/zhanlingjie/Documents/virEnv/GPapp/lib/python3.4/site-packages/django/core/handlers/base.py", line 187, in _get_response
    response = self.process_exception_by_middleware(e, request)
  File "/Users/zhanlingjie/Documents/virEnv/GPapp/lib/python3.4/site-packages/django/core/handlers/base.py", line 185, in _get_response
    response = wrapped_callback(request, *callback_args, **callback_kwargs)
  File "/Users/zhanlingjie/Documents/virEnv/GPapp/lib/python3.4/site-packages/django/views/decorators/csrf.py", line 58, in wrapped_view
    return view_func(*args, **kwargs)
  File "/Users/zhanlingjie/Documents/mypython/GG/ContentApp/views.py", line 41, in introduce
    return render(request, 'content/introduce.html', locals())
  File "/Users/zhanlingjie/Documents/virEnv/GPapp/lib/python3.4/site-packages/django/shortcuts.py", line 30, in render
    content = loader.render_to_string(template_name, context, request, using=using)
  File "/Users/zhanlingjie/Documents/virEnv/GPapp/lib/python3.4/site-packages/django/template/loader.py", line 68, in render_to_string
    return template.render(context, request)
  File "/Users/zhanlingjie/Documents/virEnv/GPapp/lib/python3.4/site-packages/django/template/backends/django.py", line 66, in render
    return self.template.render(context)
  File "/Users/zhanlingjie/Documents/virEnv/GPapp/lib/python3.4/site-packages/django/template/base.py", line 207, in render
    return self._render(context)
  File "/Users/zhanlingjie/Documents/virEnv/GPapp/lib/python3.4/site-packages/django/template/base.py", line 199, in _render
    return self.nodelist.render(context)
  File "/Users/zhanlingjie/Documents/virEnv/GPapp/lib/python3.4/site-packages/django/template/base.py", line 990, in render
    bit = node.render_annotated(context)
  File "/Users/zhanlingjie/Documents/virEnv/GPapp/lib/python3.4/site-packages/django/template/base.py", line 957, in render_annotated
    return self.render(context)
  File "/Users/zhanlingjie/Documents/virEnv/GPapp/lib/python3.4/site-packages/django/template/loader_tags.py", line 177, in render
    return compiled_parent._render(context)
  File "/Users/zhanlingjie/Documents/virEnv/GPapp/lib/python3.4/site-packages/django/template/base.py", line 199, in _render
    return self.nodelist.render(context)
  File "/Users/zhanlingjie/Documents/virEnv/GPapp/lib/python3.4/site-packages/django/template/base.py", line 990, in render
    bit = node.render_annotated(context)
  File "/Users/zhanlingjie/Documents/virEnv/GPapp/lib/python3.4/site-packages/django/template/base.py", line 957, in render_annotated
    return self.render(context)
  File "/Users/zhanlingjie/Documents/virEnv/GPapp/lib/python3.4/site-packages/django/template/defaulttags.py", line 172, in render
    values = list(values)
TypeError: 'UserInfo' object is not iterable
